<?xml version="1.0"?>
<robot name="axis_robot">

  <link name="world"></link>

  <joint name="base_leg" type="fixed">
      <origin xyz="0 10 0" rpy="0 0 0"/>
      <parent link="world"/>
      <child link="base_link"/>        
  </joint>

  <link name="base_link">
    <visual>
      <geometry>
        <cylinder length="0.01" radius="0.01"/>
      </geometry>
      <origin rpy="0 0 0" xyz="0 0 0"/>
    </visual>
  </link>

  <joint name="joint1" type="continuous">
    <origin xyz="0 0 0" rpy="-1.57 0 0" />
    <parent link="base_link"/>
    <child link="link1"/>
    <axis xyz="0 0 1" />
  </joint>
  
  <link name="link1">
    <visual>
      <geometry>
        <cylinder length="0.4" radius="0.01"/>
      </geometry>
      <origin rpy="1.57075 0 0" xyz="0 0.2 0"/>
    </visual>
  </link>



  <link name="link2">
    <visual>
      <geometry>
        <cylinder length="0.4" radius="0.01"/>
      </geometry>
      <origin rpy="1.57075 0 0" xyz="0 0.4 0"/>
    </visual>
  </link>

  <joint name="joint2" type="continuous">
    <parent link="link1"/>
    <child link="link2"/>
    <origin xyz="0 0 3" rpy="1.57 -1.57 0" />
    <axis xyz="0 0 1" />
  </joint>

  <link name="link3">
    <visual>
      <geometry>
        <cylinder length="0.4" radius="0.01"/>
      </geometry>
      <origin rpy="1.57075 0 0" xyz="0 0.6 0"/>
    </visual>
  </link>
  
  <joint name="joint3" type="continuous">
    <parent link="link2"/>
    <child link="link3"/>
    <origin xyz="0 9.4 0" rpy="0 0 1.57" />
    <axis xyz="0 0 1" />
  </joint>
</robot>